Workbook

Sheet Canteiro central
A2: Canteiro | B2: CC | F2: Rodovia | G2: extensão canteiro central
F3: SP-348 | G3: 157
A4: Rótulos de Linha | B4: Contagem de ID2 | C4: Contagem de Km inicial | F4: SP-330 | G4: 73
A5: VGSP-348_014,000_CC | B5: 1 | C5: 1 | F5: SP-102 | G5: 6
A6: VGSP-348_015,000_CC | B6: 3 | C6: 3 | F6: SP-300 | G6: 2
A7: VGSP-348_016,000_CC | B7: 4 | C7: 4 | G7: =SUM(G3:G6) -> 238
A8: VGSP-348_017,000_CC | B8: 2 | C8: 2
A9: VGSP-348_019,000_CC | B9: 1 | C9: 1
A10: VGSP-348_020,000_CC | B10: 3 | C10: 3
A11: VGSP-348_021,000_CC | B11: 3 | C11: 3
A12: VGSP-348_022,000_CC | B12: 2 | C12: 2
A13: VGSP-348_023,000_CC | B13: 2 | C13: 2 | F13: =COUNTA(A5:A161) -> 157
A14: VGSP-348_024,000_CC | B14: 4 | C14: 4
A15: VGSP-348_025,000_CC | B15: 3 | C15: 3
A16: VGSP-348_026,000_CC | B16: 3 | C16: 3
A17: VGSP-348_027,000_CC | B17: 3 | C17: 3
A18: VGSP-348_028,000_CC | B18: 3 | C18: 3
A19: VGSP-348_029,000_CC | B19: 3 | C19: 3
A20: VGSP-348_030,000_CC | B20: 1 | C20: 1
A21: VGSP-348_031,000_CC | B21: 5 | C21: 5
A22: VGSP-348_032,000_CC | B22: 2 | C22: 2
A23: VGSP-348_033,000_CC | B23: 2 | C23: 2
A24: VGSP-348_034,000_CC | B24: 3 | C24: 3
A25: VGSP-348_035,000_CC | B25: 2 | C25: 2
... A162: Total Geral | B162: 438 | C162: 438

Sheet AB 
A1: ID Motiva/Quasar | B1: Km inicial | C1: Km final | D1: DELTA KM | E1: Canteiro | F1: Sentido | G1: Latitude | H1: Longitude | I1: Área | J1: Largura média | K1: Inclinação | L1: % mecanização | M1: área mecanizada | N1: Área Pot. Mecanização | O1: Equipamento | P1: Observação | Q1: Supressão | R1: Bloqueio Físico | S1: Causas Operacionais | T1: Condições Administrativas | U1: Mecanização | V1: Mecanização
A2: VGSP-102_001,000_ES_CL3 | B2: 1,000 | C2: 1,500 | D2: =C2-B2 -> 0.5 | E2: CL | F2: =MID(A2,19,1) -> S | G2: -22.872293 | H2: -47.131861 | I2: 142.45 | K2: 4.98 | L2: 30 | N2: =IF(OR(R2="Sim",S2="Sim",T2="Sim"),(L2/100)*I2,0) -> 0 | O2: Trator 1.7m | Q2: Não | R2: Não | S2: Não | T2: Não | U2: =IF(N2=0,(I2*(L2/100)),0) -> 42.735 | V2: =(I2*(L2/100)) -> 42.735
A3: VGSP-102_001,000_CC2 | B3: 1,000 | C3: 1,500 | D3: =C3-B3 -> 0.5 | E3: CC | F3: =MID(A3,19,1) -> C | G3: -22.870649 | H3: -47.131751 | I3: 13141.37 | J3: =I3/500 -> 26.28274 | K3: 4.13 | L3: 50 | N3: =IF(OR(R3="Sim",S3="Sim",T3="Sim"),(L3/100)*I3,0) -> 0 | O3: Trator 1.7m | Q3: Não | R3: Não | S3: Não | T3: Não | U3: =IF(N3=0,(I3*(L3/100)),0) -> 6570.685 | V3: =(I3*(L3/100)) -> 6570.685
A4: VGSP-102_001,000_EN_CL1 | B4: 1,000 | C4: 1,500 | D4: =C4-B4 -> 0.5 | E4: CL | F4: =MID(A4,19,1) -> N | G4: -22.870434 | H4: -47.131452 | I4: 1782.96 | K4: 3.97 | L4: 65 | N4: =IF(OR(R4="Sim",S4="Sim",T4="Sim"),(L4/100)*I4,0) -> 1158.924 | O4: Trator com braço articulado | Q4: Não | R4: Sim | S4: Não | T4: Sim | U4: =IF(N4=0,(I4*(L4/100)),0) -> 0
A5: VGSP-102_001,000_ES_CL2 | B5: 1,000 | C5: 1,500 | D5: =C5-B5 -> 0.5 | E5: CL | F5: =MID(A5,19,1) -> S | G5: -22.872444 | H5: -47.13196 | I5: 181.51 | K5: 4.5 | L5: 30 | N5: =IF(OR(R5="Sim",S5="Sim",T5="Sim"),(L5/100)*I5,0) -> 0 | O5: Trator 1.7m | Q5: Não | R5: Não | S5: Não | T5: Não | U5: =IF(N5=0,(I5*(L5/100)),0) -> 54.453 | V5: =(I5*(L5/100)) -> 54.453
A6: VGSP-102_001,000_CC1 | B6: 1,000 | C6: 1,500 | D6: =C6-B6 -> 0.5 | E6: CC | F6: =MID(A6,19,1) -> C | G6: -22.874741 | H6: -47.13126 | I6: 14948.87 | J6: =I6/500 -> 29.89774 | K6: 3.68 | L6: 50 | N6: =IF(OR(R6="Sim",S6="Sim",T6="Sim"),(L6/100)*I6,0) -> 0 | O6: Trator 1.7m | Q6: Não | R6: Não | S6: Não | T6: Não | U6: =IF(N6=0,(I6*(L6/100)),0) -> 7474.435 | V6: =(I6*(L6/100)) -> 7474.435
A7: VGSP-102_001,000_EN_CL2 | B7: 1,000 | C7: 1,500 | D7: =C7-B7 -> 0.5 | E7: CL | F7: =MID(A7,19,1) -> N | G7: -22.8747 | H7: -47.130945 | I7: 1775.42 | K7: 5.94 | L7: 65 | N7: =IF(OR(R7="Sim",S7="Sim",T7="Sim"),(L7/100)*I7,0) -> 1154.023 | O7: Trator com braço articulado | Q7: Não | R7: Sim | S7: Não | T7: Sim | U7: =IF(N7=0,(I7*(L7/100)),0) -> 0
A8: VGSP-102_001,000_ES_CL4 | B8: 1,000 | C8: 1,500 | D8: =C8-B8 -> 0.5 | E8: CL | F8: =MID(A8,19,1) -> S | G8: -22.870436 | H8: -47.132126 | I8: 1708.11 | K8: 5 | L8: 70 | N8: =IF(OR(R8="Sim",S8="Sim",T8="Sim"),(L8/100)*I8,0) -> 1195.677 | O8: Trator com braço articulado | Q8: Não | R8: Não | S8: Não | T8: Sim | U8: =IF(N8=0,(I8*(L8/100)),0) -> 0
A9: VGSP-102_001,000_ES_CL1 | B9: 1,000 | C9: 1,500 | D9: =C9-B9 -> 0.5 | E9: CL | F9: =MID(A9,19,1) -> S | G9: -22.874752 | H9: -47.131572 | I9: 1775.38 | K9: 2.33 | L9: 70 | N9: =IF(OR(R9="Sim",S9="Sim",T9="Sim"),(L9/100)*I9,0) -> 1242.766 | O9: Trator com braço articulado | Q9: Não | R9: Não | S9: Não | T9: Sim | U9: =IF(N9=0,(I9*(L9/100)),0) -> 0
A10: VGSP-102_002,000_EN_CL1 | B10: 2,000 | C10: 2,500 | D10: =C10-B10 -> 0.5 | E10: CL | F10: =MID(A10,19,1) -> N | G10: -22.885222 | H10: -47.130885 | I10: 537.91 | K10: 3.97 | L10: 30 | N10: =IF(OR(R10="Sim",S10="Sim",T10="Sim"),(L10/100)*I10,0) -> 0 | O10: Trator 1.7m | Q10: Não | R10: Não | S10: Não | T10: Não | U10: =IF(N10=0,(I10*(L10/100)),0) -> 161.373 | V10: =(I10*(L10/100)) -> 161.373
A11: VGSP-102_002,000_ES_CL3 | B11: 2,000 | C11: 2,500 | D11: =C11-B11 -> 0.5 | E11: CL | F11: =MID(A11,19,1) -> S | G11: -22.879362 | H11: -47.13109 | I11: 2009.47 | K11: 2.55 | L11: 70 | N11: =IF(OR(R11="Sim",S11="Sim",T11="Sim"),(L11/100)*I11,0) -> 1406.629 | O11: Trator com braço articulado | Q11: Não | R11: Não | S11: Não | T11: Sim | U11: =IF(N11=0,(I11*(L11/100)),0) -> 0
A12: VGSP-102_002,000_EN_CL3 | B12: 2,000 | C12: 2,500 | D12: =C12-B12 -> 0.5 | E12: CL | F12: =MID(A12,19,1) -> N | G12: -22.883191 | H12: -47.130494 | I12: 1180.71 | K12: 1.48 | L12: 30 | N12: =IF(OR(R12="Sim",S12="Sim",T12="Sim"),(L12/100)*I12,0) -> 0 | O12: Trator 1.7m | Q12: Não | R12: Não | S12: Não | T12: Não | U12: =IF(N12=0,(I12*(L12/100)),0) -> 354.213 | V12: =(I12*(L12/100)) -> 354.213
A13: VGSP-102_002,000_CC2 | B13: 2,000 | C13: 2,500 | D13: =C13-B13 -> 0.5 | E13: CC | F13: =MID(A13,19,1) -> C | G13: -22.883124 | H13: -47.130799 | I13: 9163.46 | J13: =I13/500 -> 18.32692 | K13: 1.86 | L13: 50 | N13: =IF(OR(R13="Sim",S13="Sim",T13="Sim"),(L13/100)*I13,0) -> 0 | O13: Trator 1.7m | Q13: Não | R13: Não | S13: Não | T13: Não | U13: =IF(N13=0,(I13*(L13/100)),0) -> 4581.73 | V13: =(I13*(L13/100)) -> 4581.73
A14: VGSP-102_002,000_ES_CL1 | B14: 2,000 | C14: 2,500 | D14: =C14-B14 -> 0.5 | E14: CL | F14: =MID(A14,19,1) -> S | G14: -22.885109 | H14: -47.131492 | I14: 486.94 | K14: 4 | L14: 70 | N14: =IF(OR(R14="Sim",S14="Sim",T14="Sim"),(L14/100)*I14,0) -> 340.858 | O14: Trator com braço articulado | Q14: Não | R14: Não | S14: Não | T14: Sim | U14: =IF(N14=0,(I14*(L14/100)),0) -> 0
A15: VGSP-102_002,000_ES_CL2 | B15: 2,000 | C15: 2,500 | D15: =C15-B15 -> 0.5 | E15: CL | F15: =MID(A15,19,1) -> S | G15: -22.883142 | H15: -47.131122 | I15: 1093.43 | K15: 2.39 | L15: 70 | N15: =IF(OR(R15="Sim",S15="Sim",T15="Sim"),(L15/100)*I15,0) -> 765.401 | O15: Trator com braço articulado | Q15: Não | R15: Não | S15: Não | T15: Sim | U15: =IF(N15=0,(I15*(L15/100)),0) -> 0
A16: VGSP-102_002,000_CC3 | B16: 2,000 | C16: 2,500 | D16: =C16-B16 -> 0.5 | E16: CC | F16: =MID(A16,19,1) -> C | G16: -22.879328 | H16: -47.130776 | I16: 16782.15 | J16: =I16/500 -> 33.5643 | K16: 2.73 | L16: 50 | N16: =IF(OR(R16="Sim",S16="Sim",T16="Sim"),(L16/100)*I16,0) -> 0 | O16: Trator 1.7m | Q16: Não | R16: Não | S16: Não | T16: Não | U16: =IF(N16=0,(I16*(L16/100)),0) -> 8391.075 | V16: =(I16*(L16/100)) -> 8391.075
A17: VGSP-102_002,000_EN_CL2 | B17: 2,000 | C17: 2,500 | D17: =C17-B17 -> 0.5 | E17: CL | F17: =MID(A17,19,1) -> N | G17: -22.879305 | H17: -47.130465 | I17: 2005.28 | K17: 3.34 | L17: 30 | N17: =IF(OR(R17="Sim",S17="Sim",T17="Sim"),(L17/100)*I17,0) -> 0 | O17: Trator 1.7m | Q17: Não | R17: Não | S17: Não | T17: Não | U17: =IF(N17=0,(I17*(L17/100)),0) -> 601.584 | V17: =(I17*(L17/100)) -> 601.584
A18: VGSP-102_002,000_CC1 | B18: 2,000 | C18: 2,500 | D18: =C18-B18 -> 0.5 | E18: CC | F18: =MID(A18,19,1) -> C | G18: -22.885186 | H18: -47.13119 | I18: 4137.74 | J18: =I18/500 -> 8.27548 | K18: 3.73 | L18: 50 | N18: =IF(OR(R18="Sim",S18="Sim",T18="Sim"),(L18/100)*I18,0) -> 0 | O18: Trator 1.7m | Q18: Não | R18: Não | S18: Não | T18: Não | U18: =IF(N18=0,(I18*(L18/100)),0) -> 2068.87 | V18: =(I18*(L18/100)) -> 2068.87
A19: VGSP-102_003,000_ES_CL3 | B19: 3,000 | C19: 3,500 | D19: =C19-B19 -> 0.5 | E19: CL | F19: =MID(A19,19,1) -> S | G19: -22.887569 | H19: -47.132394 | I19: 1638 | K19: 3.99 | L19: 70 | N19: =IF(OR(R19="Sim",S19="Sim",T19="Sim"),(L19/100)*I19,0) -> 1146.6 | O19: Trator com braço articulado | Q19: Não | R19: Não | S19: Não | T19: Sim | U19: =IF(N19=0,(I19*(L19/100)),0) -> 0
A20: VGSP-102_003,000_CC3 | B20: 3,000 | C20: 3,500 | D20: =C20-B20 -> 0.5 | E20: CC | F20: =MID(A20,19,1) -> C | G20: -22.890135 | H20: -47.133174 | I20: 4566.32 | J20: =I20/500 -> 9.13264 | K20: 4.54 | L20: 50 | N20: =IF(OR(R20="Sim",S20="Sim",T20="Sim"),(L20/100)*I20,0) -> 0 | O20: Trator 1.7m | Q20: Não | R20: Não | S20: Não | T20: Não | U20: =IF(N20=0,(I20*(L20/100)),0) -> 2283.16 | V20: =(I20*(L20/100)) -> 2283.16
A21: VGSP-102_003,000_ES_CL4 | B21: 3,000 | C21: 3,500 | D21: =C21-B21 -> 0.5 | E21: CL | F21: =MID(A21,19,1) -> S | G21: -22.890032 | H21: -47.133503 | I21: 552.45 | K21: 4.98 | L21: 65 | N21: =IF(OR(R21="Sim",S21="Sim",T21="Sim"),(L21/100)*I21,0) -> 359.0925 | O21: Trator com braço articulado, Spider | Q21: Não | R21: Sim | S21: Não | T21: Sim | U21: =IF(N21=0,(I21*(L21/100)),0) -> 0
A22: VGSP-102_003,000_CC4 | B22: 3,000 | C22: 3,500 | D22: =C22-B22 -> 0.5 | E22: CC | F22: =MID(A22,19,1) -> C | G22: -22.887652 | H22: -47.132087 | I22: 13724.57 | J22: =I22/500 -> 27.44914 | K22: 3.11 | L22: 50 | N22: =IF(OR(R22="Sim",S22="Sim",T22="Sim"),(L22/100)*I22,0) -> 0 | O22: Trator 1.7m | Q22: Não | R22: Não | S22: Não | T22: Não | U22: =IF(N22=0,(I22*(L22/100)),0) -> 6862.285 | V22: =(I22*(L22/100)) -> 6862.285
A23: VGSP-102_003,000_CC2 | B23: 3,000 | C23: 3,500 | D23: =C23-B23 -> 0.5 | E23: CC | F23: =MID(A23,19,1) -> C | G23: -22.891916 | H23: -47.133986 | I23: 7322.67 | J23: =I23/500 -> 14.64534 | K23: 4.92 | L23: 50 | N23: =IF(OR(R23="Sim",S23="Sim",T23="Sim"),(L23/100)*I23,0) -> 0 | O23: Trator 1.7m | Q23: Não | R23: Não | S23: Não | T23: Não | U23: =IF(N23=0,(I23*(L23/100)),0) -> 3661.335 | V23: =(I23*(L23/100)) -> 3661.335
A24: VGSP-102_003,000_CC1 | B24: 3,000 | C24: 3,500 | D24: =C24-B24 -> 0.5 | E24: CC | F24: =MID(A24,19,1) -> C | G24: -22.893744 | H24: -47.134815 | I24: 4150.7 | J24: =I24/500 -> 8.3014 | K24: 5.23 | L24: 50 | N24: =IF(OR(R24="Sim",S24="Sim",T24="Sim"),(L24/100)*I24,0) -> 0 | O24: Trator 1.7m | Q24: Não | R24: Não | S24: Não | T24: Não | U24: =IF(N24=0,(I24*(L24/100)),0) -> 2075.35 | V24: =(I24*(L24/100)) -> 2075.35
A25: VGSP-102_003,000_EN_CL5 | B25: 3,000 | C25: 3,500 | D25: =C25-B25 -> 0.5 | E25: CL | F25: =MID(A25,19,1) -> N | G25: -22.890052 | H25: -47.132809 | I25: 397.68 | K25: 7.45 | L25: 30 | N25: =IF(OR(R25="Sim",S25="Sim",T25="Sim"),(L25/100)*I25,0) -> 0 | O25: Trator 1.7m | Q25: Não | R25: Não | S25: Não | T25: Não | U25: =IF(N25=0,(I25*(L25/100)),0) -> 119.304 | V25: =(I25*(L25/100)) -> 119.304
A26: VGSP-102_003,000_EN_CL3 | B26: 3,000 | C26: 3,500 | D26: =C26-B26 -> 0.5 | E26: CL | F26: =MID(A26,19,1) -> N | G26: -22.891976 | H26: -47.133672 | I26: 964.3 | K26: 6.28 | L26: 30 | N26: =IF(OR(R26="Sim",S26="Sim",T26="Sim"),(L26/100)*I26,0) -> 0 | O26: Trator 1.7m | Q26: Não | R26: Não | S26: Não | T26: Não | U26: =IF(N26=0,(I26*(L26/100)),0) -> 289.29 | V26: =(I26*(L26/100)) -> 289.29
A27: VGSP-102_003,000_EN_CL1 | B27: 3,000 | C27: 3,500 | D27: =C27-B27 -> 0.5 | E27: CL | F27: =MID(A27,19,1) -> N | G27: -22.893854 | H27: -47.134553 | I27: 473.99 | K27: 6.07 | L27: 30 | N27: =IF(OR(R27="Sim",S27="Sim",T27="Sim"),(L27/100)*I27,0) -> 0 | O27: Trator 1.7m | Q27: Não | R27: Não | S27: Não | T27: Não | U27: =IF(N27=0,(I27*(L27/100)),0) -> 142.197 | V27: =(I27*(L27/100)) -> 142.197
A28: VGSP-102_003,000_ES_CL2 | B28: 3,000 | C28: 3,500 | D28: =C28-B28 -> 0.5 | E28: CL | F28: =MID(A28,19,1) -> S | G28: -22.891726 | H28: -47.134252 | I28: 934.25 | K28: 4.57 | L28: 70 | N28: =IF(OR(R28="Sim",S28="Sim",T28="Sim"),(L28/100)*I28,0) -> 653.975 | O28: Trator com braço articulado | Q28: Não | R28: Não | S28: Não | T28: Sim | U28: =IF(N28=0,(I28*(L28/100)),0) -> 0
A29: VGSP-102_003,000_ES_CL1 | B29: 3,000 | C29: 3,500 | D29: =C29-B29 -> 0.5 | E29: CL | F29: =MID(A29,19,1) -> S | G29: -22.893629 | H29: -47.135105 | I29: 509.62 | K29: 4.1 | L29: 70 | N29: =IF(OR(R29="Sim",S29="Sim",T29="Sim"),(L29/100)*I29,0) -> 356.734 | O29: Trator com braço articulado | Q29: Não | R29: Não | S29: Não | T29: Sim | U29: =IF(N29=0,(I29*(L29/100)),0) -> 0
A30: VGSP-102_003,000_EN_CL4 | B30: 3,000 | C30: 3,500 | D30: =C30-B30 -> 0.5 | E30: CL | F30: =MID(A30,19,1) -> N | G30: -22.887744 | H30: -47.131795 | I30: 1636.96 | K30: 3.66 | L30: 30 | N30: =IF(OR(R30="Sim",S30="Sim",T30="Sim"),(L30/100)*I30,0) -> 0 | O30: Trator 1.7m | Q30: Não | R30: Não | S30: Não | T30: Não | U30: =IF(N30=0,(I30*(L30/100)),0) -> 491.088 | V30: =(I30*(L30/100)) -> 491.088
A31: VGSP-102_003,000_EN_CL2 | B31: 3,000 | C31: 3,500 | D31: =C31-B31 -> 0.5 | E31: CL | F31: =MID(A31,19,1) -> N | G31: -22.893195 | H31: -47.134222 | I31: 8.11 | K31: 4.08 | N31: =IF(OR(R31="Sim",S31="Sim",T31="Sim"),(L31/100)*I31,0) -> 0 | Q31: Não | R31: Não | S31: Não | T31: Não | U31: =IF(N31=0,(I31*(L31/100)),0) -> 0 | V31: =(I31*(L31/100)) -> 0
A32: VGSP-102_004,000_ES_CL2 | B32: 4,000 | C32: 4,500 | D32: =C32-B32 -> 0.5 | E32: CL | F32: =MID(A32,19,1) -> S | G32: -22.89723 | H32: -47.136582 | I32: 1223.36 | K32: 5.29 | L32: 65 | N32: =IF(OR(R32="Sim",S32="Sim",T32="Sim"),(L32/100)*I32,0) -> 795.184 | O32: Trator com braço articulado | Q32: Não | R32: Não | S32: Não | T32: Sim | U32: =IF(N32=0,(I32*(L32/100)),0) -> 0
A33: VGSP-102_004,000_EN_CL1 | B33: 4,000 | C33: 4,500 | D33: =C33-B33 -> 0.5 | E33: CL | F33: =MID(A33,19,1) -> N | G33: -22.901182 | H33: -47.136561 | I33: 1900.28 | K33: 6.35 | L33: 30 | N33: =IF(OR(R33="Sim",S33="Sim",T33="Sim"),(L33/100)*I33,0) -> 0 | O33: Trator 1.7m | Q33: Não | R33: Não | S33: Não | T33: Não | U33: =IF(N33=0,(I33*(L33/100)),0) -> 570.084 | V33: =(I33*(L33/100)) -> 570.084
A34: VGSP-102_004,000_EN_CL2 | B34: 4,000 | C34: 4,500 | D34: =C34-B34 -> 0.5 | E34: CL | F34: =MID(A34,19,1) -> N | G34: -22.8966 | H34: -47.135683 | I34: 1929.66 | K34: 4.99 | L34: 30 | N34: =IF(OR(R34="Sim",S34="Sim",T34="Sim"),(L34/100)*I34,0) -> 0 | O34: Trator 1.7m | Q34: Não | R34: Não | S34: Não | T34: Não | U34: =IF(N34=0,(I34*(L34/100)),0) -> 578.898 | V34: =(I34*(L34/100)) -> 578.898
A35: VGSP-102_004,000_CC2 | B35: 4,000 | C35: 4,500 | D35: =C35-B35 -> 0.5 | E35: CC | F35: =MID(A35,19,1) -> C | G35: -22.896514 | H35: -47.135978 | I35: 15947.51 | J35: =I35/500 -> 31.89502 | K35: 4.97 | L35: 50 | N35: =IF(OR(R35="Sim",S35="Sim",T35="Sim"),(L35/100)*I35,0) -> 0 | O35: Trator 1.7m | Q35: Não | R35: Não | S35: Não | T35: Não | U35: =IF(N35=0,(I35*(L35/100)),0) -> 7973.755 | V35: =(I35*(L35/100)) -> 7973.755
A36: VGSP-102_004,000_ES_CL3 | B36: 4,000 | C36: 4,500 | D36: =C36-B36 -> 0.5 | E36: CL | F36: =MID(A36,19,1) -> S | G36: -22.894994 | H36: -47.135724 | I36: 698.88 | K36: 4.55 | L36: 65 | N36: =IF(OR(R36="Sim",S36="Sim",T36="Sim"),(L36/100)*I36,0) -> 454.272 | O36: Trator com braço articulado | Q36: Não | R36: Sim | S36: Não | T36: Sim | U36: =IF(N36=0,(I36*(L36/100)),0) -> 0
A37: VGSP-102_004,000_CC1 | B37: 4,000 | C37: 4,500 | D37: =C37-B37 -> 0.5 | E37: CC | F37: =MID(A37,19,1) -> C | G37: -22.901126 | H37: -47.136872 | I37: 16119.56 | J37: =I37/500 -> 32.23912 | K37: 5.65 | L37: 50 | N37: =IF(OR(R37="Sim",S37="Sim",T37="Sim"),(L37/100)*I37,0) -> 0 | O37: Trator 1.7m | Q37: Não | R37: Não | S37: Não | T37: Não | U37: =IF(N37=0,(I37*(L37/100)),0) -> 8059.78 | V37: =(I37*(L37/100)) -> 8059.78
A38: VGSP-102_004,000_ES_CL1 | B38: 4,000 | C38: 4,500 | D38: =C38-B38 -> 0.5 | E38: CL | F38: =MID(A38,19,1) -> S | G38: -22.901058 | H38: -47.137176 | I38: 1951.06 | K38: 7.47 | L38: 30 | N38: =IF(OR(R38="Sim",S38="Sim",T38="Sim"),(L38/100)*I38,0) -> 0 | O38: Trator 1.7m | Q38: Não | R38: Não | S38: Não | T38: Não | U38: =IF(N38=0,(I38*(L38/100)),0) -> 585.318 | V38: =(I38*(L38/100)) -> 585.318
A39: VGSP-102_005,000_EN_CL3 | B39: 5,000 | C39: 5,500 | D39: =C39-B39 -> 0.5 | E39: CL | F39: =MID(A39,19,1) -> N | G39: -22.90764 | H39: -47.136558 | I39: 2009.54 | K39: 3.98 | L39: 70 | N39: =IF(OR(R39="Sim",S39="Sim",T39="Sim"),(L39/100)*I39,0) -> 1406.678 | O39: Spider | Q39: Não | R39: Não | S39: Não | T39: Sim | U39: =IF(N39=0,(I39*(L39/100)),0) -> 0
A40: VGSP-102_005,000_EN_CL1 | B40: 5,000 | C40: 5,500 | D40: =C40-B40 -> 0.5 | E40: CL | F40: =MID(A40,19,1) -> N | G40: -22.908965 | H40: -47.13649 | I40: 1907.39 | K40: 5.91 | L40: 60 | N40: =IF(OR(R40="Sim",S40="Sim",T40="Sim"),(L40/100)*I40,0) -> 1144.434 | O40: Trator com braço articulado | Q40: Não | R40: Não | S40: Não | T40: Sim | U40: =IF(N40=0,(I40*(L40/100)),0) -> 0
...

Sheet Resumo
B3: Item | C3: Rodovia | D3: Sentido | E3: Local | F3: km i | G3: km f | H3: Área | I3: Equipamento | J3: Causa Impeditivo atual | K3: Detalhamento
B4: 1 | C4: SP-102 | D4: Sul | E4: CL | F4: 1 | G4: 4.5 | H4: =SUM('AB '!N8:N36) -> 8717.1885 | I4: Trator com Braço Articulado | J4: Administrativa | K4: Não há equipamento no contrato atualmente
B5: 2 | C5: SP-330 | D5: Sul | E5: CL | F5: ='AB '!B65 -> 12,000 | G5: ='AB '!C65 -> 12,500 | H5: ='AB '!N65 -> 1970.205 | I5: Spider | J5: Bloqueio Físico | K5: Necessário abertura de defensa
B6: 3 | C6: SP-330 | D6: Sul | E6: CL | F6: ='AB '!B87 -> 12,000 | G6: ='AB '!C87 -> 12,500 | H6: ='AB '!N87 -> 1315.258 | I6: Spider | J6: Bloqueio Físico | K6: Necessário abertura de defensa
B7: 4 | C7: SP-330 | D7: Sul | E7: CL | F7: ='AB '!B227 -> 17,000 | G7: ='AB '!C227 -> 17,500 | H7: ='AB '!N227 -> 1315.804 | I7: Spider | J7: Bloqueio Físico | K7: Necessário abertura de defensa
B8: 5 | C8: SP-330 | D8: Sul | E8: CL | F8: ='AB '!B261 -> 18,000 | G8: ='AB '!C261 -> 18,500 | H8: ='AB '!N261 -> 2716.074 | I8: Spider | J8: Bloqueio Físico | K8: Necessário abertura de defensa
B9: 6 | C9: SP-330 | D9: Sul | E9: CL | F9: ='AB '!B273 -> 18,000 | G9: ='AB '!C273 -> 18,500 | H9: ='AB '!N273 -> 970.501 | I9: Spider | J9: Administrativa | K9: Não há equipamento no contrato atualmente | M9: *Os percentuais representam a participação de cada tipo de equipamento na área total com potencial de mecanização 186.844,31
B10: 7 | C10: SP-330 | D10: Sul | E10: CL | F10: ='AB '!B532 -> 28,000 | G10: ='AB '!C538 -> 28,500 | H10: =SUM('AB '!N532,'AB '!N538) -> 2517.871 | I10: Trator com Braço Articulado | J10: Administrativa | K10: Não há equipamento no contrato atualmente | M10: Área total pot. de mecanização | N10: Área total pot. Spider | O10: Área total pot. Trator de 1,7 m | P10: Área total pot. Trator com braço | Q10: Área total pot. Eixo Zero
B11: 8 | C11: SP-330 | D11: Sul | E11: CL | F11: ='AB '!B622 -> 33,000 | G11: ='AB '!C641 -> 34,500 | H11: =SUM('AB '!N622,'AB '!N638,'AB '!N641) -> 8119.326 | I11: Trator com Braço Articulado | J11: Administrativa | K11: Não há equipamento no contrato atualmente | M11: =SUM('AB '!N4:N3440) -> 186844.31 | N11: 76230.964 | O11: =SUM('AB '!N87,'AB '!N113,'AB '!N535) -> 8500.154 | P11: 105374.77 | Q11: =SUM('AB '!N498:N505) -> 3216.969
B12: 9 | C12: SP-330 | D12: Sul | E12: CL | F12: ='AB '!B765 -> 40,000 | G12: ='AB '!C907 -> 48,500 | H12: =SUM('AB '!N765,'AB '!N766,'AB '!N780,'AB '!N786,'AB '!N800,'AB '!N817,'AB '!N834,'AB '!N849,'AB '!N876,'AB '!N907+'AB '!N807+'AB '!N822+'AB '!N828) -> 15206.309 | I12: Trator com Braço Articulado | J12: Administrativa | K12: Não há equipamento no contrato atualmente | M12: 1 | N12: =N11/$M$11 -> 0.4079919 | O12: =O11/$M$11 -> 0.045493246 | P12: =P11/$M$11 -> 0.56397101 | Q12: =Q11/$M$11 -> 0.017217378
B13: 10 | C13: SP-330 | D13: Sul | E13: CL | F13: ='AB '!B1523 -> 73,000 | G13: ='AB '!C1523 -> 73,500 | H13: ='AB '!N1523 -> 1130.545 | I13: ='AB '!O1523 -> Trator com braço articulado | J13: Administrativa | K13: Não há equipamento no contrato atualmente
B14: 11 | C14: SP-330 | D14: Sul | E14: CL | F14: ='AB '!B1542 -> 74,000 | G14: ='AB '!C1542 -> 74,500 | H14: ='AB '!N1542 -> 1521.1885 | I14: ='AB '!O1542 -> Trator com braço articulado | J14: Administrativa | K14: Não há equipamento no contrato atualmente
B15: 12 | C15: SP-330 | D15: Sul | E15: CL | F15: ='AB '!B1553 -> 75,000 | G15: ='AB '!C1553 -> 75,500 | H15: ='AB '!N1553 -> 1216.5725 | I15: ='AB '!O1553 -> Trator com braço articulado | J15: Bloqueio Físico | K15: Necessário abertura de defensa
B16: 13 | C16: SP-330 | D16: Sul | E16: CL | F16: ='AB '!B1622 -> 78,000 | G16: ='AB '!C1622 -> 78,500 | H16: ='AB '!N1622 -> 554.82 | I16: ='AB '!O1622 -> Trator com braço articulado | J16: Administrativa | K16: Não há equipamento no contrato atualmente | M16: Equipamentos para as Áreas Potenciais de Mecanização | N16: Área potencial de mecanização de cada Equipamento | O16: Percentual em relação a área total
B17: 14 | C17: SP-330 | D17: Sul | E17: CL | F17: ='AB '!B1637 -> 79,000 | G17: ='AB '!C1641 -> 80,500 | H17: =SUM('AB '!N1637:N1641) -> 4565.906 | I17: Trator com Braço Articulado | J17: Administrativa/Bloqueio Físico | K17: Não há equipamento no contrato atualmente/ km 80 a 80+500 necessário abertura | N17: =M11 -> 186844.31 | O17: 1
B18: 15 | C18: SP-348 | D18: Sul | E18: CL | F18: ='AB '!B1951 -> 92,000 | G18: ='AB '!C1951 -> 92,500 | H18: ='AB '!N1951 -> 2800.448 | I18: ='AB '!O1951 -> Spider | J18: Administrativa | K18: Não há equipamento no contrato atualmente | M18: Spider (robô) | N18: =M11 -> 186844.31 | O18: 1
B19: 16 | C19: SP-348 | D19: Sul | E19: CL | F19: ='AB '!B2416 -> 108,000 | G19: ='AB '!C2439 -> 109,500 | H19: ='AB '!N2416+'AB '!N2439 -> 1665.888 | I19: ='AB '!O2416 -> Trator com braço articulado | J19: Bloqueio Físico | K19: Necessário abertura de defensa | M19: Trator de 1,7m | N19: =O11 -> 8500.154 | O19: 0.05
B20: 17 | C20: SP-348 | D20: Sul | E20: CL | F20: ='AB '!B2557 -> 112,000 | G20: ='AB '!C2572 -> 112,500 | H20: ='AB '!N2557+'AB '!N2572 -> 1359.032 | I20: ='AB '!O2557 -> Trator com braço articulado | J20: Administrativa | K20: Não há equipamento no contrato atualmente | M20: Trator com braço articulado | N20: =P11 -> 105374.77 | O20: =N20/N17 -> 0.56397101
B21: 18 | C21: SP-348 | D21: Sul | E21: CL | F21: ='AB '!B2568 -> 112,000 | G21: ='AB '!C2568 -> 112,500 | H21: ='AB '!N2568 -> 1088.3835 | I21: ='AB '!O2568 -> Trator com braço articulado | J21: Bloqueio Físico | K21: Necessário abertura de defensa | M21: Eixo Zero | N21: =Q11 -> 3216.969 | O21: =Q12 -> 0.017217378
B22: 19 | C22: SP-348 | D22: Sul | E22: CL | F22: ='AB '!B2794 -> 121,000 | G22: ='AB '!C2801 -> 121,500 | H22: ='AB '!N2794+'AB '!N2801 -> 2705.2865 | I22: ='AB '!O2794 -> Trator com braço articulado | J22: Bloqueio Físico | K22: Necessário abertura de defensa
B23: 20 | C23: SP-348 | D23: Sul | E23: CL | F23: ='AB '!B3081 -> 135,000 | G23: ='AB '!C3189 -> 141,500 | H23: =SUM('AB '!N3081,'AB '!N3131,'AB '!N3144,'AB '!N3159,'AB '!N3189) -> 5797.293 | I23: ='AB '!O3131 -> Trator com braço articulado | J23: Bloqueio Físico | K23: Necessário abertura de defensa
B24: 21 | C24: SP-348 | D24: Sul | E24: CL | F24: ='AB '!B3244 -> 144,000 | G24: ='AB '!C3253 -> 144,500 | H24: ='AB '!N3244+'AB '!N3253 -> 1931.1825 | I24: ='AB '!O3244 -> Trator com braço articulado | J24: Bloqueio Físico | K24: Necessário abertura de defensa | M24: Área total | N24: Área manual | O24: Área mecânico
B25: 22 | C25: SP-102 | D25: Norte | E25: CL | F25: ='AB '!B4 -> 1,000 | G25: ='AB '!C51 -> 6,500 | H25: =SUM('AB '!N4,'AB '!N7,'AB '!N40,'AB '!N51) -> 4556.233 | I25: ='AB '!O4 -> Trator com braço articulado | J25: Bloqueio Físico/ Administrativa | K25: Necessário abertura de defensa km 1 a 1+500/ Não há equipamento no contrato atualmente | M25: ='AB '!K3684 -> 9640313.2 | N25: =M25-O25 -> 4668402 | O25: ='AB '!U3684 -> 4971911.2
B26: 23 | C26: SP-102 | D26: Norte | E26: CL | F26: ='AB '!B39 -> 5,000 | G26: ='AB '!C39 -> 5,500 | H26: ='AB '!N39 -> 1406.678 | I26: ='AB '!O39 -> Spider | J26: Administrativa | K26: Não há equipamento no contrato atualmente | N26: =N25/M25 -> 0.48425833 | O26: =O25/M25 -> 0.51574167
B27: 24 | C27: SP-330 | D27: Norte | E27: CL | F27: ='AB '!B257 -> 18,000 | G27: ='AB '!C288 -> 19,500 | H27: =SUM('AB '!N257,'AB '!N262,'AB '!N282,'AB '!N288) -> 9592.271 | I27: Spider | J27: Bloqueio Físico | K27: Necessário abertura de defensa
B28: 25 | C28: SP-330 | D28: Norte | E28: CL | F28: ='AB '!B390 -> 23,000 | G28: ='AB '!C390 -> 23,500 | H28: ='AB '!N390 -> 1444.73 | I28: ='AB '!O390 -> Spider | J28: Administrativa | K28: Não há equipamento no contrato atualmente | M28: Equipamentos para as Áreas Potenciais de Mecanização - AUTOBAN
B29: 26 | C29: SP-330 | D29: Norte | E29: CL | F29: ='AB '!B530 -> 28,000 | G29: ='AB '!C555 -> 29,500 | H29: =SUM('AB '!N530,'AB '!N536,'AB '!N555) -> 3703.94 | I29: ='AB '!O530 -> Trator com braço articulado | J29: Operacional | K29: Neste cenário a terceira tem o implemento mas está quebrado
B30: 27 | C30: SP-330 | D30: Norte | E30: CL | F30: ='AB '!B587 -> 31,000 | G30: ='AB '!C654 -> 35,500 | H30: =SUM('AB '!N587,'AB '!N614,'AB '!N640,'AB '!N646,'AB '!N654) -> 5404.6395 | I30: Trator com Braço Articulado | J30: Operacional | K30: Neste cenário a terceira tem o implemento mas está quebrado | M30: Robô NAVO NV22X800 + carretinha
B31: 28 | C31: SP-330 | D31: Norte | E31: CL | F31: ='AB '!B601 -> 32,000 | G31: ='AB '!C632 -> 33,500 | H31: =SUM('AB '!N601,'AB '!N632) -> 1175.733 | I31: ='AB '!O601 -> Spider | J31: Administrativa | K31: Não há equipamento no contrato atualmente | M31: Operador do Robô
B32: 29 | C32: SP-330 | D32: Norte | E32: CL | F32: ='AB '!B716 -> 38,000 | G32: ='AB '!C716 -> 38,500 | H32: ='AB '!N716 -> 1549.827 | I32: ='AB '!O716 -> Spider | J32: Administrativa | K32: Não há equipamento no contrato atualmente | M32: Pick up utilitária
B33: 30 | C33: SP-330 | D33: Norte | E33: CL | F33: ='AB '!B763 -> 40,000 | G33: ='AB '!C899 -> 48,500 | H33: =SUM('AB '!N763,'AB '!N769,'AB '!N778,'AB '!N790,'AB '!N811,'AB '!N824,'AB '!N841,'AB '!N863,'AB '!N899) -> 8531.6305 | I33: ='AB '!O763 -> Trator com braço articulado | J33: Administrativa | K33: Não há equipamento no contrato atualmente | M33: Braço articulado articulado com roçadeira tipo faca ou tipo trincha - Para tratores até 75cv
B34: 31 | C34: SP-348 | D34: Norte | E34: CL | F34: ='AB '!B1798 -> 86,000 | G34: ='AB '!C1819 -> 87,500 | H34: =SUM('AB '!N1798,'AB '!N1819) -> 1852.911 | I34: ='AB '!O1798 -> Trator com braço articulado | J34: Bloqueio Físico | K34: Necessário abertura de defensa
B35: 32 | C35: SP-348 | D35: Norte | E35: CL | F35: ='AB '!B1963 -> 92,000 | G35: ='AB '!C1963 -> 92,500 | H35: ='AB '!N1963 -> 2117.792 | I35: ='AB '!O1963 -> Spider | J35: Administrativa | K35: Não há equipamento no contrato atualmente
B36: 33 | C36: SP-348 | D36: Norte | E36: CL | F36: ='AB '!B1959 -> 92,000 | G36: ='AB '!C1959 -> 92,500 | H36: ='AB '!N1959 -> 1303.968 | I36: ='AB '!O1959 -> Trator com braço articulado | J36: Bloqueio Físico | K36: Necessário abertura de defensa
B37: 34 | C37: SP-348 | D37: Norte | E37: CL | F37: ='AB '!B2172 -> 99,000 | G37: ='AB '!C2172 -> 99,500 | H37: ='AB '!N2172 -> 2598.864 | I37: ='AB '!O2172 -> Spider | J37: Administrativa | K37: Não há equipamento no contrato atualmente
B38: 35 | C38: SP-348 | D38: Norte | E38: CL | F38: ='AB '!B2332 -> 104,000 | G38: ='AB '!C2332 -> 104,500 | H38: ='AB '!N2332 -> 1869.936 | I38: ='AB '!O2332 -> Spider | J38: Administrativa | K38: Não há equipamento no contrato atualmente
B39: 36 | C39: SP-348 | D39: Norte | E39: CL | F39: ='AB '!B2423 -> 108,000 | G39: ='AB '!C2450 -> 109,500 | H39: ='AB '!N2423+'AB '!N2450 -> 2397.892 | I39: ='AB '!O2423 -> Trator com braço articulado | J39: Bloqueio Físico | K39: Necessário abertura de defensa
B40: 37 | C40: SP-348 | D40: Norte | E40: CL | F40: ='AB '!B2447 -> 109,000 | G40: ='AB '!C2447 -> 109,500 | H40: ='AB '!N2447 -> 275.2945 | I40: ='AB '!O2447 -> Spider | J40: Bloqueio Físico | K40: Necessário abertura de defensa
B41: 38 | C41: SP-348 | D41: Norte | E41: CL | F41: ='AB '!B2569 -> 112,000 | G41: ='AB '!C2573 -> 112,500 | H41: =SUM('AB '!N2569:N2573) -> 3778.558 | I41: ='AB '!O2569 -> Trator com braço articulado | J41: Bloqueio Físico | K41: Necessário abertura de defensa
B42: 39 | C42: SP-348 | D42: Norte | E42: CL | F42: ='AB '!B2688 -> 116,000 | G42: ='AB '!C2700 -> 117,500 | H42: ='AB '!N2688+'AB '!N2700 -> 2402.964 | I42: ='AB '!O2688 -> Trator com braço articulado | J42: Bloqueio Físico | K42: Necessário abertura de defensa
...
